<?xml version="1.0" encoding="utf-8" ?>
<!-- =================================================================================== -->
<!-- |    This document was autogenerated by xacro from /home/taira/work/ws_kortex_ros/src/ros_kortex/kortex_description/multiple_robots/kortex_dual_robots.xacro | -->
<!-- |    EDITING THIS FILE BY HAND IS NOT RECOMMENDED                                 | -->
<!-- =================================================================================== -->
<robot name="dual_robot">
    <link name="world" />
    <joint name="world_to_leftroot" type="fixed">
        <child link="leftbase_link" />
        <parent link="world" />
        <!-- Here you can change the origin of the left arm-->
        <origin rpy="0 0 0" xyz="-1 0 0" />
    </joint>
    <joint name="world_to_rightroot" type="fixed">
        <child link="rightbase_link" />
        <parent link="world" />
        <!-- Here you can change the origin of the right arm -->
        <origin rpy="0 0 0" xyz="1 0 0" />
    </joint>
    <!-- Run the macros -->
    <link name="leftbase_link">

        <inertial>
            <origin rpy="0 0 0" xyz="-0.000648 -0.000166 0.084487" />
            <mass value="1.697" />
            <inertia ixx="0.004622" ixy="9E-06" ixz="6E-05" iyy="0.004495" iyz="9E-06" izz="0.002079" />
        </inertial>

        <visual>
            <origin rpy="0 0 0" xyz="0 0 0" />
            <geometry>
                <mesh filename="package://kortex_description/arms/gen3/7dof/meshes/base_link.STL" />
            </geometry>
            <material name="">
                <color rgba="0.75294 0.75294 0.75294 1" />
            </material>
        </visual>
        <collision>
            <origin rpy="0 0 0" xyz="0 0 0" />
            <geometry>
                <mesh filename="package://kortex_description/arms/gen3/7dof/meshes/base_link.STL" />
            </geometry>
        </collision>
    </link>
    <link name="leftshoulder_link">

        <inertial>
            <origin rpy="0 0 0" xyz="-2.3E-05 -0.010364 -0.07336" />
            <mass value="1.3773" />
            <inertia ixx="0.00457" ixy="1E-06" ixz="2E-06" iyy="0.004831" iyz="0.000448" izz="0.001409" />
        </inertial>

        <visual>
            <origin rpy="0 0 0" xyz="0 0 0" />
            <geometry>
                <mesh filename="package://kortex_description/arms/gen3/7dof/meshes/shoulder_link.STL" />
            </geometry>
            <material name="">
                <color rgba="0.75294 0.75294 0.75294 1" />
            </material>
        </visual>
        <collision>
            <origin rpy="0 0 0" xyz="0 0 0" />
            <geometry>
                <mesh filename="package://kortex_description/arms/gen3/7dof/meshes/shoulder_link.STL" />
            </geometry>
        </collision>
    </link>
    <joint name="leftjoint_1" type="continuous">
        <origin rpy="3.1416 2.7629E-18 -4.9305E-36" xyz="0 0 0.15643" />
        <parent link="leftbase_link" />
        <child link="leftshoulder_link" />
        <axis xyz="0 0 1" />
        <limit effort="39" velocity="1.3963" />
    </joint>
    <link name="lefthalf_arm_1_link">

        <inertial>
            <origin rpy="0 0 0" xyz="-4.4E-05 -0.09958 -0.013278" />
            <mass value="1.1636" />
            <inertia ixx="0.011088" ixy="5E-06" ixz="0" iyy="0.001072" iyz="-0.000691" izz="0.011255" />
        </inertial>

        <visual>
            <origin rpy="0 0 0" xyz="0 0 0" />
            <geometry>
                <mesh filename="package://kortex_description/arms/gen3/7dof/meshes/half_arm_1_link.STL" />
            </geometry>
            <material name="">
                <color rgba="0.75294 0.75294 0.75294 1" />
            </material>
        </visual>
        <collision>
            <origin rpy="0 0 0" xyz="0 0 0" />
            <geometry>
                <mesh filename="package://kortex_description/arms/gen3/7dof/meshes/half_arm_1_link.STL" />
            </geometry>
        </collision>
    </link>
    <joint name="leftjoint_2" type="revolute">
        <origin rpy="1.5708 2.1343E-17 -1.1102E-16" xyz="0 0.005375 -0.12838" />
        <parent link="leftshoulder_link" />
        <child link="lefthalf_arm_1_link" />
        <axis xyz="0 0 1" />
        <limit effort="39" lower="-2.41" upper="2.41" velocity="1.3963" />
    </joint>
    <link name="lefthalf_arm_2_link">

        <inertial>
            <origin rpy="0 0 0" xyz="-4.4E-05 -0.006641 -0.117892" />
            <mass value="1.1636" />
            <inertia ixx="0.010932" ixy="0" ixz="-7E-06" iyy="0.011127" iyz="0.000606" izz="0.001043" />
        </inertial>

        <visual>
            <origin rpy="0 0 0" xyz="0 0 0" />
            <geometry>
                <mesh filename="package://kortex_description/arms/gen3/7dof/meshes/half_arm_2_link.STL" />
            </geometry>
            <material name="">
                <color rgba="0.75294 0.75294 0.75294 1" />
            </material>
        </visual>
        <collision>
            <origin rpy="0 0 0" xyz="0 0 0" />
            <geometry>
                <mesh filename="package://kortex_description/arms/gen3/7dof/meshes/half_arm_2_link.STL" />
            </geometry>
        </collision>
    </link>
    <joint name="leftjoint_3" type="continuous">
        <origin rpy="-1.5708 1.2326E-32 -2.9122E-16" xyz="0 -0.21038 -0.006375" />
        <parent link="lefthalf_arm_1_link" />
        <child link="lefthalf_arm_2_link" />
        <axis xyz="0 0 1" />
        <limit effort="39" velocity="1.3963" />
    </joint>
    <link name="leftforearm_link">

        <inertial>
            <origin rpy="0 0 0" xyz="-1.8E-05 -0.075478 -0.015006" />
            <mass value="0.9302" />
            <inertia ixx="0.008147" ixy="-1E-06" ixz="0" iyy="0.000631" iyz="-0.0005" izz="0.008316" />
        </inertial>

        <visual>
            <origin rpy="0 0 0" xyz="0 0 0" />
            <geometry>
                <mesh filename="package://kortex_description/arms/gen3/7dof/meshes/forearm_link.STL" />
            </geometry>
            <material name="">
                <color rgba="0.75294 0.75294 0.75294 1" />
            </material>
        </visual>
        <collision>
            <origin rpy="0 0 0" xyz="0 0 0" />
            <geometry>
                <mesh filename="package://kortex_description/arms/gen3/7dof/meshes/forearm_link.STL" />
            </geometry>
        </collision>
    </link>
    <joint name="leftjoint_4" type="revolute">
        <origin rpy="1.5708 -6.6954E-17 -1.6653E-16" xyz="0 0.006375 -0.21038" />
        <parent link="lefthalf_arm_2_link" />
        <child link="leftforearm_link" />
        <axis xyz="0 0 1" />
        <limit effort="39" lower="-2.66" upper="2.66" velocity="1.3963" />
    </joint>
    <link name="leftspherical_wrist_1_link">

        <inertial>
            <origin rpy="0 0 0" xyz="1E-06 -0.009432 -0.063883" />
            <mass value="0.6781" />
            <inertia ixx="0.001596" ixy="0" ixz="0" iyy="0.001607" iyz="0.000256" izz="0.000399" />
        </inertial>

        <visual>
            <origin rpy="0 0 0" xyz="0 0 0" />
            <geometry>
                <mesh filename="package://kortex_description/arms/gen3/7dof/meshes/spherical_wrist_1_link.STL" />
            </geometry>
            <material name="">
                <color rgba="0.75294 0.75294 0.75294 1" />
            </material>
        </visual>
        <collision>
            <origin rpy="0 0 0" xyz="0 0 0" />
            <geometry>
                <mesh filename="package://kortex_description/arms/gen3/7dof/meshes/spherical_wrist_1_link.STL" />
            </geometry>
        </collision>
    </link>
    <joint name="leftjoint_5" type="continuous">
        <origin rpy="-1.5708 2.2204E-16 -6.373E-17" xyz="0 -0.20843 -0.006375" />
        <parent link="leftforearm_link" />
        <child link="leftspherical_wrist_1_link" />
        <axis xyz="0 0 1" />
        <limit effort="9" velocity="1.2218" />
    </joint>
    <link name="leftspherical_wrist_2_link">

        <inertial>
            <origin rpy="0 0 0" xyz="1E-06 -0.045483 -0.00965" />
            <mass value="0.6781" />
            <inertia ixx="0.001641" ixy="0" ixz="0" iyy="0.00041" iyz="-0.000278" izz="0.001641" />
        </inertial>

        <visual>
            <origin rpy="0 0 0" xyz="0 0 0" />
            <geometry>
                <mesh filename="package://kortex_description/arms/gen3/7dof/meshes/spherical_wrist_2_link.STL" />
            </geometry>
            <material name="">
                <color rgba="0.75294 0.75294 0.75294 1" />
            </material>
        </visual>
        <collision>
            <origin rpy="0 0 0" xyz="0 0 0" />
            <geometry>
                <mesh filename="package://kortex_description/arms/gen3/7dof/meshes/spherical_wrist_2_link.STL" />
            </geometry>
        </collision>
    </link>
    <joint name="leftjoint_6" type="revolute">
        <origin rpy="1.5708 9.2076E-28 -8.2157E-15" xyz="0 0.00017505 -0.10593" />
        <parent link="leftspherical_wrist_1_link" />
        <child link="leftspherical_wrist_2_link" />
        <axis xyz="0 0 1" />
        <limit effort="9" lower="-2.23" upper="2.23" velocity="1.2218" />
    </joint>
    <link name="leftbracelet_link">

        <inertial>
            <origin rpy="0 0 0" xyz="0.000281 0.011402 -0.029798" />
            <mass value="0.5" />
            <inertia ixx="0.000587" ixy="3E-06" ixz="3E-06" iyy="0.000369" iyz="-0.000118" izz="0.000609" />
        </inertial>

        <visual>
            <origin rpy="0 0 0" xyz="0 0 0" />
            <geometry>
                <mesh filename="package://kortex_description/arms/gen3/7dof/meshes/bracelet_with_vision_link.STL" />
            </geometry>
            <material name="">
                <color rgba="0.75294 0.75294 0.75294 1" />
            </material>
        </visual>
        <collision>
            <origin rpy="0 0 0" xyz="0 0 0" />
            <geometry>
                <mesh filename="package://kortex_description/arms/gen3/7dof/meshes/bracelet_with_vision_link.STL" />
            </geometry>
        </collision>
    </link>
    <joint name="leftjoint_7" type="continuous">
        <origin rpy="-1.5708 -5.5511E-17 9.6396E-17" xyz="0 -0.10593 -0.00017505" />
        <parent link="leftspherical_wrist_2_link" />
        <child link="leftbracelet_link" />
        <axis xyz="0 0 1" />
        <limit effort="9" velocity="1.2218" />
    </joint>
    <link name="leftend_effector_link" />
    <joint name="leftend_effector" type="fixed">
        <origin rpy="3.14159265358979 1.09937075168372E-32 0" xyz="0 0 -0.0615250000000001" />
        <parent link="leftbracelet_link" />
        <child link="leftend_effector_link" />
        <axis xyz="0 0 0" />
    </joint>
    <!-- Run the macros -->
    <link name="rightbase_link">

        <inertial>
            <origin rpy="0 0 0" xyz="-0.000648 -0.000166 0.084487" />
            <mass value="1.697" />
            <inertia ixx="0.004622" ixy="9E-06" ixz="6E-05" iyy="0.004495" iyz="9E-06" izz="0.002079" />
        </inertial>

        <visual>
            <origin rpy="0 0 0" xyz="0 0 0" />
            <geometry>
                <mesh filename="package://kortex_description/arms/gen3/7dof/meshes/base_link.STL" />
            </geometry>
            <material name="">
                <color rgba="0.75294 0.75294 0.75294 1" />
            </material>
        </visual>
        <collision>
            <origin rpy="0 0 0" xyz="0 0 0" />
            <geometry>
                <mesh filename="package://kortex_description/arms/gen3/7dof/meshes/base_link.STL" />
            </geometry>
        </collision>
    </link>
    <link name="rightshoulder_link">

        <inertial>
            <origin rpy="0 0 0" xyz="-2.3E-05 -0.010364 -0.07336" />
            <mass value="1.3773" />
            <inertia ixx="0.00457" ixy="1E-06" ixz="2E-06" iyy="0.004831" iyz="0.000448" izz="0.001409" />
        </inertial>

        <visual>
            <origin rpy="0 0 0" xyz="0 0 0" />
            <geometry>
                <mesh filename="package://kortex_description/arms/gen3/7dof/meshes/shoulder_link.STL" />
            </geometry>
            <material name="">
                <color rgba="0.75294 0.75294 0.75294 1" />
            </material>
        </visual>
        <collision>
            <origin rpy="0 0 0" xyz="0 0 0" />
            <geometry>
                <mesh filename="package://kortex_description/arms/gen3/7dof/meshes/shoulder_link.STL" />
            </geometry>
        </collision>
    </link>
    <joint name="rightjoint_1" type="continuous">
        <origin rpy="3.1416 2.7629E-18 -4.9305E-36" xyz="0 0 0.15643" />
        <parent link="rightbase_link" />
        <child link="rightshoulder_link" />
        <axis xyz="0 0 1" />
        <limit effort="39" velocity="1.3963" />
    </joint>
    <link name="righthalf_arm_1_link">

        <inertial>
            <origin rpy="0 0 0" xyz="-4.4E-05 -0.09958 -0.013278" />
            <mass value="1.1636" />
            <inertia ixx="0.011088" ixy="5E-06" ixz="0" iyy="0.001072" iyz="-0.000691" izz="0.011255" />
        </inertial>

        <visual>
            <origin rpy="0 0 0" xyz="0 0 0" />
            <geometry>
                <mesh filename="package://kortex_description/arms/gen3/7dof/meshes/half_arm_1_link.STL" />
            </geometry>
            <material name="">
                <color rgba="0.75294 0.75294 0.75294 1" />
            </material>
        </visual>
        <collision>
            <origin rpy="0 0 0" xyz="0 0 0" />
            <geometry>
                <mesh filename="package://kortex_description/arms/gen3/7dof/meshes/half_arm_1_link.STL" />
            </geometry>
        </collision>
    </link>
    <joint name="rightjoint_2" type="revolute">
        <origin rpy="1.5708 2.1343E-17 -1.1102E-16" xyz="0 0.005375 -0.12838" />
        <parent link="rightshoulder_link" />
        <child link="righthalf_arm_1_link" />
        <axis xyz="0 0 1" />
        <limit effort="39" lower="-2.41" upper="2.41" velocity="1.3963" />
    </joint>
    <link name="righthalf_arm_2_link">

        <inertial>
            <origin rpy="0 0 0" xyz="-4.4E-05 -0.006641 -0.117892" />
            <mass value="1.1636" />
            <inertia ixx="0.010932" ixy="0" ixz="-7E-06" iyy="0.011127" iyz="0.000606" izz="0.001043" />
        </inertial>

        <visual>
            <origin rpy="0 0 0" xyz="0 0 0" />
            <geometry>
                <mesh filename="package://kortex_description/arms/gen3/7dof/meshes/half_arm_2_link.STL" />
            </geometry>
            <material name="">
                <color rgba="0.75294 0.75294 0.75294 1" />
            </material>
        </visual>
        <collision>
            <origin rpy="0 0 0" xyz="0 0 0" />
            <geometry>
                <mesh filename="package://kortex_description/arms/gen3/7dof/meshes/half_arm_2_link.STL" />
            </geometry>
        </collision>
    </link>
    <joint name="rightjoint_3" type="continuous">
        <origin rpy="-1.5708 1.2326E-32 -2.9122E-16" xyz="0 -0.21038 -0.006375" />
        <parent link="righthalf_arm_1_link" />
        <child link="righthalf_arm_2_link" />
        <axis xyz="0 0 1" />
        <limit effort="39" velocity="1.3963" />
    </joint>
    <link name="rightforearm_link">

        <inertial>
            <origin rpy="0 0 0" xyz="-1.8E-05 -0.075478 -0.015006" />
            <mass value="0.9302" />
            <inertia ixx="0.008147" ixy="-1E-06" ixz="0" iyy="0.000631" iyz="-0.0005" izz="0.008316" />
        </inertial>

        <visual>
            <origin rpy="0 0 0" xyz="0 0 0" />
            <geometry>
                <mesh filename="package://kortex_description/arms/gen3/7dof/meshes/forearm_link.STL" />
            </geometry>
            <material name="">
                <color rgba="0.75294 0.75294 0.75294 1" />
            </material>
        </visual>
        <collision>
            <origin rpy="0 0 0" xyz="0 0 0" />
            <geometry>
                <mesh filename="package://kortex_description/arms/gen3/7dof/meshes/forearm_link.STL" />
            </geometry>
        </collision>
    </link>
    <joint name="rightjoint_4" type="revolute">
        <origin rpy="1.5708 -6.6954E-17 -1.6653E-16" xyz="0 0.006375 -0.21038" />
        <parent link="righthalf_arm_2_link" />
        <child link="rightforearm_link" />
        <axis xyz="0 0 1" />
        <limit effort="39" lower="-2.66" upper="2.66" velocity="1.3963" />
    </joint>
    <link name="rightspherical_wrist_1_link">

        <inertial>
            <origin rpy="0 0 0" xyz="1E-06 -0.009432 -0.063883" />
            <mass value="0.6781" />
            <inertia ixx="0.001596" ixy="0" ixz="0" iyy="0.001607" iyz="0.000256" izz="0.000399" />
        </inertial>

        <visual>
            <origin rpy="0 0 0" xyz="0 0 0" />
            <geometry>
                <mesh filename="package://kortex_description/arms/gen3/7dof/meshes/spherical_wrist_1_link.STL" />
            </geometry>
            <material name="">
                <color rgba="0.75294 0.75294 0.75294 1" />
            </material>
        </visual>
        <collision>
            <origin rpy="0 0 0" xyz="0 0 0" />
            <geometry>
                <mesh filename="package://kortex_description/arms/gen3/7dof/meshes/spherical_wrist_1_link.STL" />
            </geometry>
        </collision>
    </link>
    <joint name="rightjoint_5" type="continuous">
        <origin rpy="-1.5708 2.2204E-16 -6.373E-17" xyz="0 -0.20843 -0.006375" />
        <parent link="rightforearm_link" />
        <child link="rightspherical_wrist_1_link" />
        <axis xyz="0 0 1" />
        <limit effort="9" velocity="1.2218" />
    </joint>
    <link name="rightspherical_wrist_2_link">

        <inertial>
            <origin rpy="0 0 0" xyz="1E-06 -0.045483 -0.00965" />
            <mass value="0.6781" />
            <inertia ixx="0.001641" ixy="0" ixz="0" iyy="0.00041" iyz="-0.000278" izz="0.001641" />
        </inertial>

        <visual>
            <origin rpy="0 0 0" xyz="0 0 0" />
            <geometry>
                <mesh filename="package://kortex_description/arms/gen3/7dof/meshes/spherical_wrist_2_link.STL" />
            </geometry>
            <material name="">
                <color rgba="0.75294 0.75294 0.75294 1" />
            </material>
        </visual>
        <collision>
            <origin rpy="0 0 0" xyz="0 0 0" />
            <geometry>
                <mesh filename="package://kortex_description/arms/gen3/7dof/meshes/spherical_wrist_2_link.STL" />
            </geometry>
        </collision>
    </link>
    <joint name="rightjoint_6" type="revolute">
        <origin rpy="1.5708 9.2076E-28 -8.2157E-15" xyz="0 0.00017505 -0.10593" />
        <parent link="rightspherical_wrist_1_link" />
        <child link="rightspherical_wrist_2_link" />
        <axis xyz="0 0 1" />
        <limit effort="9" lower="-2.23" upper="2.23" velocity="1.2218" />
    </joint>
    <link name="rightbracelet_link">

        <inertial>
            <origin rpy="0 0 0" xyz="0.000281 0.011402 -0.029798" />
            <mass value="0.5" />
            <inertia ixx="0.000587" ixy="3E-06" ixz="3E-06" iyy="0.000369" iyz="-0.000118" izz="0.000609" />
        </inertial>

        <visual>
            <origin rpy="0 0 0" xyz="0 0 0" />
            <geometry>
                <mesh filename="package://kortex_description/arms/gen3/7dof/meshes/bracelet_with_vision_link.STL" />
            </geometry>
            <material name="">
                <color rgba="0.75294 0.75294 0.75294 1" />
            </material>
        </visual>
        <collision>
            <origin rpy="0 0 0" xyz="0 0 0" />
            <geometry>
                <mesh filename="package://kortex_description/arms/gen3/7dof/meshes/bracelet_with_vision_link.STL" />
            </geometry>
        </collision>
    </link>
    <joint name="rightjoint_7" type="continuous">
        <origin rpy="-1.5708 -5.5511E-17 9.6396E-17" xyz="0 -0.10593 -0.00017505" />
        <parent link="rightspherical_wrist_2_link" />
        <child link="rightbracelet_link" />
        <axis xyz="0 0 1" />
        <limit effort="9" velocity="1.2218" />
    </joint>
    <link name="rightend_effector_link" />
    <joint name="rightend_effector" type="fixed">
        <origin rpy="3.14159265358979 1.09937075168372E-32 0" xyz="0 0 -0.0615250000000001" />
        <parent link="rightbracelet_link" />
        <child link="rightend_effector_link" />
        <axis xyz="0 0 0" />
    </joint>
    <!-- This line was removed by Kinova because we replaced the transmission file with our own
    <xacro:include filename="$(find robotiq_2f_85_gripper_visualization)/urdf/robotiq_arg2f_transmission.xacro" /> -->
    <!-- This joint was added by Kinova -->
    <joint name="rightgripper_base_joint" type="fixed">
        <parent link="rightend_effector_link" />
        <child link="rightrobotiq_arg2f_base_link" />
        <origin rpy="0.0 0.0 1.57" xyz="0.0 0.0 0.0" />
    </joint>
    <link name="rightrobotiq_arg2f_base_link">

        <inertial>
            <origin rpy="0 0 0" xyz="8.625E-08 -4.6583E-06 0.03145" />
            <mass value="0.22652" />
            <inertia ixx="0.00020005" ixy="-4.2442E-10" ixz="-2.9069E-10" iyy="0.00017832" iyz="-3.4402E-08" izz="0.00013478" />
        </inertial>

        <visual>
            <origin rpy="0 0 0" xyz="0 0 0" />
            <geometry>
                <!-- The DAE file doesn't show well in Gazebo so we're using the STL instead -->
                <!-- <mesh filename="package://kortex_description/grippers/robotiq_2f_85/meshes/visual/robotiq_arg2f_85_base_link.dae" scale="0.001 0.001 0.001"/> -->
                <mesh filename="package://kortex_description/grippers/robotiq_2f_85/meshes/collision/robotiq_arg2f_base_link.stl" />
            </geometry>
            <material name="">
                <color rgba="0.1 0.1 0.1 1" />
            </material>
        </visual>
        <collision>
            <origin rpy="0 0 0" xyz="0 0 0" />
            <geometry>
                <mesh filename="package://kortex_description/grippers/robotiq_2f_85/meshes/collision/robotiq_arg2f_base_link.stl" />
            </geometry>
        </collision>
    </link>
    <gazebo reference="rightrobotiq_arg2f_base_link">
        <material>Gazebo/Black</material>
    </gazebo>
    <link name="rightleft_outer_knuckle">

        <inertial>
            <origin rpy="0 0 0" xyz="-0.000200000000003065 0.0199435877845359 0.0292245259211331" />
            <mass value="0.00853198276973456" />
            <inertia ixx="2.89328108496468E-06" ixy="-1.57935047237397E-19" ixz="-1.93980378593255E-19" iyy="1.86719750325683E-06" iyz="-1.21858577871576E-06" izz="1.21905238907251E-06" />
        </inertial>

        <visual>
            <origin rpy="0 0 0" xyz="0 0 0" />
            <geometry>
                <mesh filename="package://kortex_description/grippers/robotiq_2f_85/meshes/visual/robotiq_arg2f_85_outer_knuckle.dae" scale="0.001 0.001 0.001" />
            </geometry>
            <material name="">
                <color rgba="0.792156862745098 0.819607843137255 0.933333333333333 1" />
            </material>
        </visual>
        <collision>
            <origin rpy="0 0 0" xyz="0 0 0" />
            <geometry>
                <mesh filename="package://kortex_description/grippers/robotiq_2f_85/meshes/collision/robotiq_arg2f_85_outer_knuckle.dae" scale="0.001 0.001 0.001" />
            </geometry>
        </collision>
    </link>
    <link name="rightleft_outer_finger">

        <inertial>
            <origin rpy="0 0 0" xyz="0.00030115855001899 0.0373907951953854 -0.0208027427000385" />
            <mass value="0.022614240507152" />
            <inertia ixx="1.52518312458174E-05" ixy="9.76583423954399E-10" ixz="-5.43838577022588E-10" iyy="6.17694243867776E-06" iyz="6.78636130740228E-06" izz="1.16494917907219E-05" />
        </inertial>

        <visual>
            <origin rpy="0 0 0" xyz="0 0 0" />
            <geometry>
                <mesh filename="package://kortex_description/grippers/robotiq_2f_85/meshes/visual/robotiq_arg2f_85_outer_finger.dae" scale="0.001 0.001 0.001" />
            </geometry>
            <material name="">
                <color rgba="0.1 0.1 0.1 1" />
            </material>
        </visual>
        <collision>
            <origin rpy="0 0 0" xyz="0 0 0" />
            <geometry>
                <mesh filename="package://kortex_description/grippers/robotiq_2f_85/meshes/collision/robotiq_arg2f_85_outer_finger.dae" scale="0.001 0.001 0.001" />
            </geometry>
        </collision>
    </link>
    <link name="rightleft_inner_finger">

        <inertial>
            <origin rpy="0 0 0" xyz="0.000299999999999317 0.0160078233491243 -0.0136945669206257" />
            <mass value="0.0104003125914103" />
            <inertia ixx="2.71909453810972E-06" ixy="1.35402465472579E-21" ixz="-7.1817349065269E-22" iyy="7.69100314106116E-07" iyz="6.74715432769696E-07" izz="2.30315190420171E-06" />
        </inertial>

        <visual>
            <origin rpy="0 0 0" xyz="0 0 0" />
            <geometry>
                <mesh filename="package://kortex_description/grippers/robotiq_2f_85/meshes/visual/robotiq_arg2f_85_inner_finger.dae" scale="0.001 0.001 0.001" />
            </geometry>
            <material name="">
                <color rgba="0.1 0.1 0.1 1" />
            </material>
        </visual>
        <collision>
            <origin rpy="0 0 0" xyz="0 0 0" />
            <geometry>
                <mesh filename="package://kortex_description/grippers/robotiq_2f_85/meshes/collision/robotiq_arg2f_85_inner_finger.dae" scale="0.001 0.001 0.001" />
            </geometry>
        </collision>
    </link>
    <link name="rightleft_inner_finger_pad">
        <visual>
            <origin rpy="0 0 0" xyz="0 0 0" />
            <geometry>
                <box size="0.022 0.00635 0.0375" />
            </geometry>
            <material name="">
                <color rgba="0.9 0.9 0.9 1" />
            </material>
        </visual>
        <collision>
            <origin rpy="0 0 0" xyz="0 0 0" />
            <geometry>
                <box size="0.022 0.00635 0.0375" />
            </geometry>
            <material name="">
                <color rgba="0.9 0.0 0.0 1" />
            </material>
        </collision>

        <inertial>
            <mass value="0.1" />
            <inertia ixx="0.03" iyy="0.03" izz="0.03" ixy="0.0" ixz="0.0" iyz="0.0" />
        </inertial>

    </link>
    <link name="rightleft_inner_knuckle">

        <inertial>
            <origin rpy="0 0 0" xyz="0.000123011831763771 0.0507850843201817 0.00103968640075166" />
            <mass value="0.0271177346495152" />
            <inertia ixx="2.61910379223783E-05" ixy="-2.43616858946494E-07" ixz="-6.37789906117123E-09" iyy="2.8270243746167E-06" iyz="-5.37200748039765E-07" izz="2.83695868220296E-05" />
        </inertial>

        <visual>
            <origin rpy="0 0 0" xyz="0 0 0" />
            <geometry>
                <mesh filename="package://kortex_description/grippers/robotiq_2f_85/meshes/visual/robotiq_arg2f_85_inner_knuckle.dae" scale="0.001 0.001 0.001" />
            </geometry>
            <material name="">
                <color rgba="0.1 0.1 0.1 1" />
            </material>
        </visual>
        <collision>
            <origin rpy="0 0 0" xyz="0 0 0" />
            <geometry>
                <mesh filename="package://kortex_description/grippers/robotiq_2f_85/meshes/collision/robotiq_arg2f_85_inner_knuckle.dae" scale="0.001 0.001 0.001" />
            </geometry>
        </collision>
    </link>
    <link name="rightright_outer_knuckle">

        <inertial>
            <origin rpy="0 0 0" xyz="-0.000200000000003065 0.0199435877845359 0.0292245259211331" />
            <mass value="0.00853198276973456" />
            <inertia ixx="2.89328108496468E-06" ixy="-1.57935047237397E-19" ixz="-1.93980378593255E-19" iyy="1.86719750325683E-06" iyz="-1.21858577871576E-06" izz="1.21905238907251E-06" />
        </inertial>

        <visual>
            <origin rpy="0 0 0" xyz="0 0 0" />
            <geometry>
                <mesh filename="package://kortex_description/grippers/robotiq_2f_85/meshes/visual/robotiq_arg2f_85_outer_knuckle.dae" scale="0.001 0.001 0.001" />
            </geometry>
            <material name="">
                <color rgba="0.792156862745098 0.819607843137255 0.933333333333333 1" />
            </material>
        </visual>
        <collision>
            <origin rpy="0 0 0" xyz="0 0 0" />
            <geometry>
                <mesh filename="package://kortex_description/grippers/robotiq_2f_85/meshes/collision/robotiq_arg2f_85_outer_knuckle.dae" scale="0.001 0.001 0.001" />
            </geometry>
        </collision>
    </link>
    <link name="rightright_outer_finger">

        <inertial>
            <origin rpy="0 0 0" xyz="0.00030115855001899 0.0373907951953854 -0.0208027427000385" />
            <mass value="0.022614240507152" />
            <inertia ixx="1.52518312458174E-05" ixy="9.76583423954399E-10" ixz="-5.43838577022588E-10" iyy="6.17694243867776E-06" iyz="6.78636130740228E-06" izz="1.16494917907219E-05" />
        </inertial>

        <visual>
            <origin rpy="0 0 0" xyz="0 0 0" />
            <geometry>
                <mesh filename="package://kortex_description/grippers/robotiq_2f_85/meshes/visual/robotiq_arg2f_85_outer_finger.dae" scale="0.001 0.001 0.001" />
            </geometry>
            <material name="">
                <color rgba="0.1 0.1 0.1 1" />
            </material>
        </visual>
        <collision>
            <origin rpy="0 0 0" xyz="0 0 0" />
            <geometry>
                <mesh filename="package://kortex_description/grippers/robotiq_2f_85/meshes/collision/robotiq_arg2f_85_outer_finger.dae" scale="0.001 0.001 0.001" />
            </geometry>
        </collision>
    </link>
    <link name="rightright_inner_finger">

        <inertial>
            <origin rpy="0 0 0" xyz="0.000299999999999317 0.0160078233491243 -0.0136945669206257" />
            <mass value="0.0104003125914103" />
            <inertia ixx="2.71909453810972E-06" ixy="1.35402465472579E-21" ixz="-7.1817349065269E-22" iyy="7.69100314106116E-07" iyz="6.74715432769696E-07" izz="2.30315190420171E-06" />
        </inertial>

        <visual>
            <origin rpy="0 0 0" xyz="0 0 0" />
            <geometry>
                <mesh filename="package://kortex_description/grippers/robotiq_2f_85/meshes/visual/robotiq_arg2f_85_inner_finger.dae" scale="0.001 0.001 0.001" />
            </geometry>
            <material name="">
                <color rgba="0.1 0.1 0.1 1" />
            </material>
        </visual>
        <collision>
            <origin rpy="0 0 0" xyz="0 0 0" />
            <geometry>
                <mesh filename="package://kortex_description/grippers/robotiq_2f_85/meshes/collision/robotiq_arg2f_85_inner_finger.dae" scale="0.001 0.001 0.001" />
            </geometry>
        </collision>
    </link>
    <link name="rightright_inner_finger_pad">
        <visual>
            <origin rpy="0 0 0" xyz="0 0 0" />
            <geometry>
                <box size="0.022 0.00635 0.0375" />
            </geometry>
            <material name="">
                <color rgba="0.9 0.9 0.9 1" />
            </material>
        </visual>
        <collision>
            <origin rpy="0 0 0" xyz="0 0 0" />
            <geometry>
                <box size="0.022 0.00635 0.0375" />
            </geometry>
            <material name="">
                <color rgba="0.9 0.0 0.0 1" />
            </material>
        </collision>

        <inertial>
            <mass value="0.1" />
            <inertia ixx="0.03" iyy="0.03" izz="0.03" ixy="0.0" ixz="0.0" iyz="0.0" />
        </inertial>

    </link>
    <link name="rightright_inner_knuckle">

        <inertial>
            <origin rpy="0 0 0" xyz="0.000123011831763771 0.0507850843201817 0.00103968640075166" />
            <mass value="0.0271177346495152" />
            <inertia ixx="2.61910379223783E-05" ixy="-2.43616858946494E-07" ixz="-6.37789906117123E-09" iyy="2.8270243746167E-06" iyz="-5.37200748039765E-07" izz="2.83695868220296E-05" />
        </inertial>

        <visual>
            <origin rpy="0 0 0" xyz="0 0 0" />
            <geometry>
                <mesh filename="package://kortex_description/grippers/robotiq_2f_85/meshes/visual/robotiq_arg2f_85_inner_knuckle.dae" scale="0.001 0.001 0.001" />
            </geometry>
            <material name="">
                <color rgba="0.1 0.1 0.1 1" />
            </material>
        </visual>
        <collision>
            <origin rpy="0 0 0" xyz="0 0 0" />
            <geometry>
                <mesh filename="package://kortex_description/grippers/robotiq_2f_85/meshes/collision/robotiq_arg2f_85_inner_knuckle.dae" scale="0.001 0.001 0.001" />
            </geometry>
        </collision>
    </link>
    <joint name="rightfinger_joint" type="revolute">
        <origin rpy="0 0 3.14159265359" xyz="0 -0.0306011 0.054904" />
        <parent link="rightrobotiq_arg2f_base_link" />
        <child link="rightleft_outer_knuckle" />
        <axis xyz="1 0 0" />
        <limit effort="1000" lower="0" upper="0.8" velocity="2.0" />
    </joint>
    <joint name="rightleft_outer_finger_joint" type="fixed">
        <origin rpy="0 0 0" xyz="0 0.0315 -0.0041" />
        <parent link="rightleft_outer_knuckle" />
        <child link="rightleft_outer_finger" />
        <axis xyz="1 0 0" />
    </joint>
    <joint name="rightleft_inner_knuckle_joint" type="revolute">
        <!-- <origin xyz="0 ${reflect * -0.0127} 0.06142" rpy="${pi / 2 + .725} 0 ${(reflect - 1) * pi / 2}" /> -->
        <origin rpy="0 0 3.14159265359" xyz="0 -0.0127 0.06142" />
        <parent link="rightrobotiq_arg2f_base_link" />
        <child link="rightleft_inner_knuckle" />
        <axis xyz="1 0 0" />
        <limit effort="1000" lower="0" upper="0.8757" velocity="2.0" />
        <mimic joint="rightfinger_joint" multiplier="1" offset="0" />
    </joint>
    <joint name="rightleft_inner_finger_joint" type="revolute">
        <origin rpy="0 0 0" xyz="0 0.0061 0.0471" />
        <parent link="rightleft_outer_finger" />
        <child link="rightleft_inner_finger" />
        <axis xyz="1 0 0" />
        <limit effort="1000" lower="-0.8757" upper="0.8757" velocity="2.0" />
        <mimic joint="rightfinger_joint" multiplier="-1" offset="0" />
    </joint>
    <joint name="rightleft_inner_finger_pad_joint" type="fixed">
        <origin rpy="0 0 0" xyz="0 -0.0220203446692936 0.03242" />
        <parent link="rightleft_inner_finger" />
        <child link="rightleft_inner_finger_pad" />
        <axis xyz="0 0 1" />
    </joint>
    <joint name="rightright_outer_knuckle_joint" type="revolute">
        <origin rpy="0 0 0" xyz="0 0.0306011 0.054904" />
        <parent link="rightrobotiq_arg2f_base_link" />
        <child link="rightright_outer_knuckle" />
        <axis xyz="1 0 0" />
        <limit effort="1000" lower="0" upper="0.81" velocity="2.0" />
        <mimic joint="rightfinger_joint" multiplier="1" offset="0" />
    </joint>
    <joint name="rightright_outer_finger_joint" type="fixed">
        <origin rpy="0 0 0" xyz="0 0.0315 -0.0041" />
        <parent link="rightright_outer_knuckle" />
        <child link="rightright_outer_finger" />
        <axis xyz="1 0 0" />
    </joint>
    <joint name="rightright_inner_knuckle_joint" type="revolute">
        <!-- <origin xyz="0 ${reflect * -0.0127} 0.06142" rpy="${pi / 2 + .725} 0 ${(reflect - 1) * pi / 2}" /> -->
        <origin rpy="0 0 0.0" xyz="0 0.0127 0.06142" />
        <parent link="rightrobotiq_arg2f_base_link" />
        <child link="rightright_inner_knuckle" />
        <axis xyz="1 0 0" />
        <limit effort="1000" lower="0" upper="0.8757" velocity="2.0" />
        <mimic joint="rightfinger_joint" multiplier="1" offset="0" />
    </joint>
    <joint name="rightright_inner_finger_joint" type="revolute">
        <origin rpy="0 0 0" xyz="0 0.0061 0.0471" />
        <parent link="rightright_outer_finger" />
        <child link="rightright_inner_finger" />
        <axis xyz="1 0 0" />
        <limit effort="1000" lower="-0.8757" upper="0.8757" velocity="2.0" />
        <mimic joint="rightfinger_joint" multiplier="-1" offset="0" />
    </joint>
    <joint name="rightright_inner_finger_pad_joint" type="fixed">
        <origin rpy="0 0 0" xyz="0 -0.0220203446692936 0.03242" />
        <parent link="rightright_inner_finger" />
        <child link="rightright_inner_finger_pad" />
        <axis xyz="0 0 1" />
    </joint>
    <!-- Transmissions are loaded in the generic kortex xacro when simulation is enabled -->
    <!-- <xacro:robotiq_arg2f_transmission prefix="${prefix}"/> -->

    <transmission name="trans_leftjoint_1">
        <type>transmission_interface/SimpleTransmission</type>
        <joint name="leftjoint_1">
            <hardwareInterface>hardware_interface/EffortJointInterface</hardwareInterface>
        </joint>
        <actuator name="leftjoint_1_motor">
            <hardwareInterface>hardware_interface/EffortJointInterface</hardwareInterface>
            <mechanicalReduction>1</mechanicalReduction>
        </actuator>
    </transmission>
    <transmission name="trans_leftjoint_2">
        <type>transmission_interface/SimpleTransmission</type>
        <joint name="leftjoint_2">
            <hardwareInterface>hardware_interface/EffortJointInterface</hardwareInterface>
        </joint>
        <actuator name="leftjoint_2_motor">
            <hardwareInterface>hardware_interface/EffortJointInterface</hardwareInterface>
            <mechanicalReduction>1</mechanicalReduction>
        </actuator>
    </transmission>
    <transmission name="trans_leftjoint_3">
        <type>transmission_interface/SimpleTransmission</type>
        <joint name="leftjoint_3">
            <hardwareInterface>hardware_interface/EffortJointInterface</hardwareInterface>
        </joint>
        <actuator name="leftjoint_3_motor">
            <hardwareInterface>hardware_interface/EffortJointInterface</hardwareInterface>
            <mechanicalReduction>1</mechanicalReduction>
        </actuator>
    </transmission>
    <transmission name="trans_leftjoint_4">
        <type>transmission_interface/SimpleTransmission</type>
        <joint name="leftjoint_4">
            <hardwareInterface>hardware_interface/EffortJointInterface</hardwareInterface>
        </joint>
        <actuator name="leftjoint_4_motor">
            <hardwareInterface>hardware_interface/EffortJointInterface</hardwareInterface>
            <mechanicalReduction>1</mechanicalReduction>
        </actuator>
    </transmission>
    <transmission name="trans_leftjoint_5">
        <type>transmission_interface/SimpleTransmission</type>
        <joint name="leftjoint_5">
            <hardwareInterface>hardware_interface/EffortJointInterface</hardwareInterface>
        </joint>
        <actuator name="leftjoint_5_motor">
            <hardwareInterface>hardware_interface/EffortJointInterface</hardwareInterface>
            <mechanicalReduction>1</mechanicalReduction>
        </actuator>
    </transmission>
    <transmission name="trans_leftjoint_6">
        <type>transmission_interface/SimpleTransmission</type>
        <joint name="leftjoint_6">
            <hardwareInterface>hardware_interface/EffortJointInterface</hardwareInterface>
        </joint>
        <actuator name="leftjoint_6_motor">
            <hardwareInterface>hardware_interface/EffortJointInterface</hardwareInterface>
            <mechanicalReduction>1</mechanicalReduction>
        </actuator>
    </transmission>
    <transmission name="trans_leftjoint_7">
        <type>transmission_interface/SimpleTransmission</type>
        <joint name="leftjoint_7">
            <hardwareInterface>hardware_interface/EffortJointInterface</hardwareInterface>
        </joint>
        <actuator name="leftjoint_7_motor">
            <hardwareInterface>hardware_interface/EffortJointInterface</hardwareInterface>
            <mechanicalReduction>1</mechanicalReduction>
        </actuator>
    </transmission>
    <transmission name="trans_rightjoint_1">
        <type>transmission_interface/SimpleTransmission</type>
        <joint name="rightjoint_1">
            <hardwareInterface>hardware_interface/EffortJointInterface</hardwareInterface>
        </joint>
        <actuator name="rightjoint_1_motor">
            <hardwareInterface>hardware_interface/EffortJointInterface</hardwareInterface>
            <mechanicalReduction>1</mechanicalReduction>
        </actuator>
    </transmission>
    <transmission name="trans_rightjoint_2">
        <type>transmission_interface/SimpleTransmission</type>
        <joint name="rightjoint_2">
            <hardwareInterface>hardware_interface/EffortJointInterface</hardwareInterface>
        </joint>
        <actuator name="rightjoint_2_motor">
            <hardwareInterface>hardware_interface/EffortJointInterface</hardwareInterface>
            <mechanicalReduction>1</mechanicalReduction>
        </actuator>
    </transmission>
    <transmission name="trans_rightjoint_3">
        <type>transmission_interface/SimpleTransmission</type>
        <joint name="rightjoint_3">
            <hardwareInterface>hardware_interface/EffortJointInterface</hardwareInterface>
        </joint>
        <actuator name="rightjoint_3_motor">
            <hardwareInterface>hardware_interface/EffortJointInterface</hardwareInterface>
            <mechanicalReduction>1</mechanicalReduction>
        </actuator>
    </transmission>
    <transmission name="trans_rightjoint_4">
        <type>transmission_interface/SimpleTransmission</type>
        <joint name="rightjoint_4">
            <hardwareInterface>hardware_interface/EffortJointInterface</hardwareInterface>
        </joint>
        <actuator name="rightjoint_4_motor">
            <hardwareInterface>hardware_interface/EffortJointInterface</hardwareInterface>
            <mechanicalReduction>1</mechanicalReduction>
        </actuator>
    </transmission>
    <transmission name="trans_rightjoint_5">
        <type>transmission_interface/SimpleTransmission</type>
        <joint name="rightjoint_5">
            <hardwareInterface>hardware_interface/EffortJointInterface</hardwareInterface>
        </joint>
        <actuator name="rightjoint_5_motor">
            <hardwareInterface>hardware_interface/EffortJointInterface</hardwareInterface>
            <mechanicalReduction>1</mechanicalReduction>
        </actuator>
    </transmission>
    <transmission name="trans_rightjoint_6">
        <type>transmission_interface/SimpleTransmission</type>
        <joint name="rightjoint_6">
            <hardwareInterface>hardware_interface/EffortJointInterface</hardwareInterface>
        </joint>
        <actuator name="rightjoint_6_motor">
            <hardwareInterface>hardware_interface/EffortJointInterface</hardwareInterface>
            <mechanicalReduction>1</mechanicalReduction>
        </actuator>
    </transmission>
    <transmission name="trans_rightjoint_7">
        <type>transmission_interface/SimpleTransmission</type>
        <joint name="rightjoint_7">
            <hardwareInterface>hardware_interface/EffortJointInterface</hardwareInterface>
        </joint>
        <actuator name="rightjoint_7_motor">
            <hardwareInterface>hardware_interface/EffortJointInterface</hardwareInterface>
            <mechanicalReduction>1</mechanicalReduction>
        </actuator>
    </transmission>
    <transmission name="trans_rightfinger_joint">
        <type>transmission_interface/SimpleTransmission</type>
        <joint name="rightfinger_joint">
            <hardwareInterface>hardware_interface/EffortJointInterface</hardwareInterface>
        </joint>
        <actuator name="rightfinger_joint_motor">
            <hardwareInterface>hardware_interface/EffortJointInterface</hardwareInterface>
            <mechanicalReduction>1</mechanicalReduction>
        </actuator>
    </transmission>
    <transmission name="trans_rightleft_inner_knuckle_joint">
        <type>transmission_interface/SimpleTransmission</type>
        <joint name="rightleft_inner_knuckle_joint">
            <hardwareInterface>hardware_interface/EffortJointInterface</hardwareInterface>
        </joint>
        <actuator name="rightleft_inner_knuckle_joint_motor">
            <hardwareInterface>hardware_interface/EffortJointInterface</hardwareInterface>
            <mechanicalReduction>1</mechanicalReduction>
        </actuator>
    </transmission>
    <transmission name="trans_rightleft_inner_finger_joint">
        <type>transmission_interface/SimpleTransmission</type>
        <joint name="rightleft_inner_finger_joint">
            <hardwareInterface>hardware_interface/EffortJointInterface</hardwareInterface>
        </joint>
        <actuator name="rightleft_inner_finger_joint_motor">
            <hardwareInterface>hardware_interface/EffortJointInterface</hardwareInterface>
            <mechanicalReduction>1</mechanicalReduction>
        </actuator>
    </transmission>
    <transmission name="trans_rightright_outer_knuckle_joint">
        <type>transmission_interface/SimpleTransmission</type>
        <joint name="rightright_outer_knuckle_joint">
            <hardwareInterface>hardware_interface/EffortJointInterface</hardwareInterface>
        </joint>
        <actuator name="rightright_outer_knuckle_joint_motor">
            <hardwareInterface>hardware_interface/EffortJointInterface</hardwareInterface>
            <mechanicalReduction>1</mechanicalReduction>
        </actuator>
    </transmission>
    <transmission name="trans_rightright_inner_knuckle_joint">
        <type>transmission_interface/SimpleTransmission</type>
        <joint name="rightright_inner_knuckle_joint">
            <hardwareInterface>hardware_interface/EffortJointInterface</hardwareInterface>
        </joint>
        <actuator name="rightright_inner_knuckle_joint_motor">
            <hardwareInterface>hardware_interface/EffortJointInterface</hardwareInterface>
            <mechanicalReduction>1</mechanicalReduction>
        </actuator>
    </transmission>
    <transmission name="trans_rightright_inner_finger_joint">
        <type>transmission_interface/SimpleTransmission</type>
        <joint name="rightright_inner_finger_joint">
            <hardwareInterface>hardware_interface/EffortJointInterface</hardwareInterface>
        </joint>
        <actuator name="rightright_inner_finger_joint_motor">
            <hardwareInterface>hardware_interface/EffortJointInterface</hardwareInterface>
            <mechanicalReduction>1</mechanicalReduction>
        </actuator>
    </transmission>
    <gazebo>
        <plugin name="gazebo_ros_control" filename="libgazebo_ros_control.so">
            <robotNamespace>/</robotNamespace>
        </plugin>
    </gazebo>
</robot>