<?xml version="1.0" encoding="utf-8" ?>
<!-- =================================================================================== -->
<!-- |    This document was autogenerated by xacro from /home/taira/work/ws_kortex_ros/src/ros_kortex/kortex_description/multiple_robots/kortex_dual_robots.xacro | -->
<!-- |    EDITING THIS FILE BY HAND IS NOT RECOMMENDED                                 | -->
<!-- =================================================================================== -->
<robot name="dual_robot">
    <link name="world"/>
    <joint name="world_to_leftroot" type="fixed">
        <child link="leftbase_link"/>
        <parent link="world"/>
        <!-- Here you can change the origin of the left arm-->
        <origin rpy="0 0 0" xyz="-1 0 0"/>
    </joint>
    <joint name="world_to_rightroot" type="fixed">
        <child link="rightbase_link"/>
        <parent link="world"/>
        <!-- Here you can change the origin of the right arm -->
        <origin rpy="0 0 0" xyz="1 0 0"/>
    </joint>
    <!-- Run the macros -->
    <link name="leftbase_link">

        <inertial>
            <origin rpy="0 0 0" xyz="-0.000648 -0.000166 0.084487"/>
            <mass value="1.697"/>
            <inertia ixx="0.004622" ixy="9E-06" ixz="6E-05" iyy="0.004495" iyz="9E-06" izz="0.002079"/>
        </inertial>

        <visual>
            <origin rpy="0 0 0" xyz="0 0 0"/>
            <geometry>
                <mesh filename="package://kortex_description/arms/gen3/7dof/meshes/base_link.STL"/>
            </geometry>
            <material name="">
                <color rgba="0.75294 0.75294 0.75294 1"/>
            </material>
        </visual>
        <collision>
            <origin rpy="0 0 0" xyz="0 0 0"/>
            <geometry>
                <mesh filename="package://kortex_description/arms/gen3/7dof/meshes/base_link.STL"/>
            </geometry>
        </collision>
    </link>
    <link name="leftshoulder_link">

        <inertial>
            <origin rpy="0 0 0" xyz="-2.3E-05 -0.010364 -0.07336"/>
            <mass value="1.3773"/>
            <inertia ixx="0.00457" ixy="1E-06" ixz="2E-06" iyy="0.004831" iyz="0.000448" izz="0.001409"/>
        </inertial>

        <visual>
            <origin rpy="0 0 0" xyz="0 0 0"/>
            <geometry>
                <mesh filename="package://kortex_description/arms/gen3/7dof/meshes/shoulder_link.STL"/>
            </geometry>
            <material name="">
                <color rgba="0.75294 0.75294 0.75294 1"/>
            </material>
        </visual>
        <collision>
            <origin rpy="0 0 0" xyz="0 0 0"/>
            <geometry>
                <mesh filename="package://kortex_description/arms/gen3/7dof/meshes/shoulder_link.STL"/>
            </geometry>
        </collision>
    </link>
    <joint name="leftjoint_1" type="continuous">
        <origin rpy="3.1416 2.7629E-18 -4.9305E-36" xyz="0 0 0.15643"/>
        <parent link="leftbase_link"/>
        <child link="leftshoulder_link"/>
        <axis xyz="0 0 1"/>
        <limit effort="39" velocity="1.3963"/>
    </joint>
    <link name="lefthalf_arm_1_link">

        <inertial>
            <origin rpy="0 0 0" xyz="-4.4E-05 -0.09958 -0.013278"/>
            <mass value="1.1636"/>
            <inertia ixx="0.011088" ixy="5E-06" ixz="0" iyy="0.001072" iyz="-0.000691" izz="0.011255"/>
        </inertial>

        <visual>
            <origin rpy="0 0 0" xyz="0 0 0"/>
            <geometry>
                <mesh filename="package://kortex_description/arms/gen3/7dof/meshes/half_arm_1_link.STL"/>
            </geometry>
            <material name="">
                <color rgba="0.75294 0.75294 0.75294 1"/>
            </material>
        </visual>
        <collision>
            <origin rpy="0 0 0" xyz="0 0 0"/>
            <geometry>
                <mesh filename="package://kortex_description/arms/gen3/7dof/meshes/half_arm_1_link.STL"/>
            </geometry>
        </collision>
    </link>
    <joint name="leftjoint_2" type="revolute">
        <origin rpy="1.5708 2.1343E-17 -1.1102E-16" xyz="0 0.005375 -0.12838"/>
        <parent link="leftshoulder_link"/>
        <child link="lefthalf_arm_1_link"/>
        <axis xyz="0 0 1"/>
        <limit effort="39" lower="-2.41" upper="2.41" velocity="1.3963"/>
    </joint>
    <link name="lefthalf_arm_2_link">

        <inertial>
            <origin rpy="0 0 0" xyz="-4.4E-05 -0.006641 -0.117892"/>
            <mass value="1.1636"/>
            <inertia ixx="0.010932" ixy="0" ixz="-7E-06" iyy="0.011127" iyz="0.000606" izz="0.001043"/>
        </inertial>

        <visual>
            <origin rpy="0 0 0" xyz="0 0 0"/>
            <geometry>
                <mesh filename="package://kortex_description/arms/gen3/7dof/meshes/half_arm_2_link.STL"/>
            </geometry>
            <material name="">
                <color rgba="0.75294 0.75294 0.75294 1"/>
            </material>
        </visual>
        <collision>
            <origin rpy="0 0 0" xyz="0 0 0"/>
            <geometry>
                <mesh filename="package://kortex_description/arms/gen3/7dof/meshes/half_arm_2_link.STL"/>
            </geometry>
        </collision>
    </link>
    <joint name="leftjoint_3" type="continuous">
        <origin rpy="-1.5708 1.2326E-32 -2.9122E-16" xyz="0 -0.21038 -0.006375"/>
        <parent link="lefthalf_arm_1_link"/>
        <child link="lefthalf_arm_2_link"/>
        <axis xyz="0 0 1"/>
        <limit effort="39" velocity="1.3963"/>
    </joint>
    <link name="leftforearm_link">

        <inertial>
            <origin rpy="0 0 0" xyz="-1.8E-05 -0.075478 -0.015006"/>
            <mass value="0.9302"/>
            <inertia ixx="0.008147" ixy="-1E-06" ixz="0" iyy="0.000631" iyz="-0.0005" izz="0.008316"/>
        </inertial>

        <visual>
            <origin rpy="0 0 0" xyz="0 0 0"/>
            <geometry>
                <mesh filename="package://kortex_description/arms/gen3/7dof/meshes/forearm_link.STL"/>
            </geometry>
            <material name="">
                <color rgba="0.75294 0.75294 0.75294 1"/>
            </material>
        </visual>
        <collision>
            <origin rpy="0 0 0" xyz="0 0 0"/>
            <geometry>
                <mesh filename="package://kortex_description/arms/gen3/7dof/meshes/forearm_link.STL"/>
            </geometry>
        </collision>
    </link>
    <joint name="leftjoint_4" type="revolute">
        <origin rpy="1.5708 -6.6954E-17 -1.6653E-16" xyz="0 0.006375 -0.21038"/>
        <parent link="lefthalf_arm_2_link"/>
        <child link="leftforearm_link"/>
        <axis xyz="0 0 1"/>
        <limit effort="39" lower="-2.66" upper="2.66" velocity="1.3963"/>
    </joint>
    <link name="leftspherical_wrist_1_link">

        <inertial>
            <origin rpy="0 0 0" xyz="1E-06 -0.009432 -0.063883"/>
            <mass value="0.6781"/>
            <inertia ixx="0.001596" ixy="0" ixz="0" iyy="0.001607" iyz="0.000256" izz="0.000399"/>
        </inertial>

        <visual>
            <origin rpy="0 0 0" xyz="0 0 0"/>
            <geometry>
                <mesh filename="package://kortex_description/arms/gen3/7dof/meshes/spherical_wrist_1_link.STL"/>
            </geometry>
            <material name="">
                <color rgba="0.75294 0.75294 0.75294 1"/>
            </material>
        </visual>
        <collision>
            <origin rpy="0 0 0" xyz="0 0 0"/>
            <geometry>
                <mesh filename="package://kortex_description/arms/gen3/7dof/meshes/spherical_wrist_1_link.STL"/>
            </geometry>
        </collision>
    </link>
    <joint name="leftjoint_5" type="continuous">
        <origin rpy="-1.5708 2.2204E-16 -6.373E-17" xyz="0 -0.20843 -0.006375"/>
        <parent link="leftforearm_link"/>
        <child link="leftspherical_wrist_1_link"/>
        <axis xyz="0 0 1"/>
        <limit effort="9" velocity="1.2218"/>
    </joint>
    <link name="leftspherical_wrist_2_link">

        <inertial>
            <origin rpy="0 0 0" xyz="1E-06 -0.045483 -0.00965"/>
            <mass value="0.6781"/>
            <inertia ixx="0.001641" ixy="0" ixz="0" iyy="0.00041" iyz="-0.000278" izz="0.001641"/>
        </inertial>

        <visual>
            <origin rpy="0 0 0" xyz="0 0 0"/>
            <geometry>
                <mesh filename="package://kortex_description/arms/gen3/7dof/meshes/spherical_wrist_2_link.STL"/>
            </geometry>
            <material name="">
                <color rgba="0.75294 0.75294 0.75294 1"/>
            </material>
        </visual>
        <collision>
            <origin rpy="0 0 0" xyz="0 0 0"/>
            <geometry>
                <mesh filename="package://kortex_description/arms/gen3/7dof/meshes/spherical_wrist_2_link.STL"/>
            </geometry>
        </collision>
    </link>
    <joint name="leftjoint_6" type="revolute">
        <origin rpy="1.5708 9.2076E-28 -8.2157E-15" xyz="0 0.00017505 -0.10593"/>
        <parent link="leftspherical_wrist_1_link"/>
        <child link="leftspherical_wrist_2_link"/>
        <axis xyz="0 0 1"/>
        <limit effort="9" lower="-2.23" upper="2.23" velocity="1.2218"/>
    </joint>
    <link name="leftbracelet_link">

        <inertial>
            <origin rpy="0 0 0" xyz="0.000281 0.011402 -0.029798"/>
            <mass value="0.5"/>
            <inertia ixx="0.000587" ixy="3E-06" ixz="3E-06" iyy="0.000369" iyz="-0.000118" izz="0.000609"/>
        </inertial>

        <visual>
            <origin rpy="0 0 0" xyz="0 0 0"/>
            <geometry>
                <mesh filename="package://kortex_description/arms/gen3/7dof/meshes/bracelet_with_vision_link.STL"/>
            </geometry>
            <material name="">
                <color rgba="0.75294 0.75294 0.75294 1"/>
            </material>
        </visual>
        <collision>
            <origin rpy="0 0 0" xyz="0 0 0"/>
            <geometry>
                <mesh filename="package://kortex_description/arms/gen3/7dof/meshes/bracelet_with_vision_link.STL"/>
            </geometry>
        </collision>
    </link>
    <joint name="leftjoint_7" type="continuous">
        <origin rpy="-1.5708 -5.5511E-17 9.6396E-17" xyz="0 -0.10593 -0.00017505"/>
        <parent link="leftspherical_wrist_2_link"/>
        <child link="leftbracelet_link"/>
        <axis xyz="0 0 1"/>
        <limit effort="9" velocity="1.2218"/>
    </joint>
    <link name="leftend_effector_link"/>
    <joint name="leftend_effector" type="fixed">
        <origin rpy="3.14159265358979 1.09937075168372E-32 0" xyz="0 0 -0.0615250000000001"/>
        <parent link="leftbracelet_link"/>
        <child link="leftend_effector_link"/>
        <axis xyz="0 0 0"/>
    </joint>
    <!-- Run the macros -->
    <link name="rightbase_link">

        <inertial>
            <origin rpy="0 0 0" xyz="-0.000648 -0.000166 0.084487"/>
            <mass value="1.697"/>
            <inertia ixx="0.004622" ixy="9E-06" ixz="6E-05" iyy="0.004495" iyz="9E-06" izz="0.002079"/>
        </inertial>

        <visual>
            <origin rpy="0 0 0" xyz="0 0 0"/>
            <geometry>
                <mesh filename="package://kortex_description/arms/gen3/7dof/meshes/base_link.STL"/>
            </geometry>
            <material name="">
                <color rgba="0.75294 0.75294 0.75294 1"/>
            </material>
        </visual>
        <collision>
            <origin rpy="0 0 0" xyz="0 0 0"/>
            <geometry>
                <mesh filename="package://kortex_description/arms/gen3/7dof/meshes/base_link.STL"/>
            </geometry>
        </collision>
    </link>
    <link name="rightshoulder_link">

        <inertial>
            <origin rpy="0 0 0" xyz="-2.3E-05 -0.010364 -0.07336"/>
            <mass value="1.3773"/>
            <inertia ixx="0.00457" ixy="1E-06" ixz="2E-06" iyy="0.004831" iyz="0.000448" izz="0.001409"/>
        </inertial>

        <visual>
            <origin rpy="0 0 0" xyz="0 0 0"/>
            <geometry>
                <mesh filename="package://kortex_description/arms/gen3/7dof/meshes/shoulder_link.STL"/>
            </geometry>
            <material name="">
                <color rgba="0.75294 0.75294 0.75294 1"/>
            </material>
        </visual>
        <collision>
            <origin rpy="0 0 0" xyz="0 0 0"/>
            <geometry>
                <mesh filename="package://kortex_description/arms/gen3/7dof/meshes/shoulder_link.STL"/>
            </geometry>
        </collision>
    </link>
    <joint name="rightjoint_1" type="continuous">
        <origin rpy="3.1416 2.7629E-18 -4.9305E-36" xyz="0 0 0.15643"/>
        <parent link="rightbase_link"/>
        <child link="rightshoulder_link"/>
        <axis xyz="0 0 1"/>
        <limit effort="39" velocity="1.3963"/>
    </joint>
    <link name="righthalf_arm_1_link">

        <inertial>
            <origin rpy="0 0 0" xyz="-4.4E-05 -0.09958 -0.013278"/>
            <mass value="1.1636"/>
            <inertia ixx="0.011088" ixy="5E-06" ixz="0" iyy="0.001072" iyz="-0.000691" izz="0.011255"/>
        </inertial>

        <visual>
            <origin rpy="0 0 0" xyz="0 0 0"/>
            <geometry>
                <mesh filename="package://kortex_description/arms/gen3/7dof/meshes/half_arm_1_link.STL"/>
            </geometry>
            <material name="">
                <color rgba="0.75294 0.75294 0.75294 1"/>
            </material>
        </visual>
        <collision>
            <origin rpy="0 0 0" xyz="0 0 0"/>
            <geometry>
                <mesh filename="package://kortex_description/arms/gen3/7dof/meshes/half_arm_1_link.STL"/>
            </geometry>
        </collision>
    </link>
    <joint name="rightjoint_2" type="revolute">
        <origin rpy="1.5708 2.1343E-17 -1.1102E-16" xyz="0 0.005375 -0.12838"/>
        <parent link="rightshoulder_link"/>
        <child link="righthalf_arm_1_link"/>
        <axis xyz="0 0 1"/>
        <limit effort="39" lower="-2.41" upper="2.41" velocity="1.3963"/>
    </joint>
    <link name="righthalf_arm_2_link">

        <inertial>
            <origin rpy="0 0 0" xyz="-4.4E-05 -0.006641 -0.117892"/>
            <mass value="1.1636"/>
            <inertia ixx="0.010932" ixy="0" ixz="-7E-06" iyy="0.011127" iyz="0.000606" izz="0.001043"/>
        </inertial>

        <visual>
            <origin rpy="0 0 0" xyz="0 0 0"/>
            <geometry>
                <mesh filename="package://kortex_description/arms/gen3/7dof/meshes/half_arm_2_link.STL"/>
            </geometry>
            <material name="">
                <color rgba="0.75294 0.75294 0.75294 1"/>
            </material>
        </visual>
        <collision>
            <origin rpy="0 0 0" xyz="0 0 0"/>
            <geometry>
                <mesh filename="package://kortex_description/arms/gen3/7dof/meshes/half_arm_2_link.STL"/>
            </geometry>
        </collision>
    </link>
    <joint name="rightjoint_3" type="continuous">
        <origin rpy="-1.5708 1.2326E-32 -2.9122E-16" xyz="0 -0.21038 -0.006375"/>
        <parent link="righthalf_arm_1_link"/>
        <child link="righthalf_arm_2_link"/>
        <axis xyz="0 0 1"/>
        <limit effort="39" velocity="1.3963"/>
    </joint>
    <link name="rightforearm_link">

        <inertial>
            <origin rpy="0 0 0" xyz="-1.8E-05 -0.075478 -0.015006"/>
            <mass value="0.9302"/>
            <inertia ixx="0.008147" ixy="-1E-06" ixz="0" iyy="0.000631" iyz="-0.0005" izz="0.008316"/>
        </inertial>

        <visual>
            <origin rpy="0 0 0" xyz="0 0 0"/>
            <geometry>
                <mesh filename="package://kortex_description/arms/gen3/7dof/meshes/forearm_link.STL"/>
            </geometry>
            <material name="">
                <color rgba="0.75294 0.75294 0.75294 1"/>
            </material>
        </visual>
        <collision>
            <origin rpy="0 0 0" xyz="0 0 0"/>
            <geometry>
                <mesh filename="package://kortex_description/arms/gen3/7dof/meshes/forearm_link.STL"/>
            </geometry>
        </collision>
    </link>
    <joint name="rightjoint_4" type="revolute">
        <origin rpy="1.5708 -6.6954E-17 -1.6653E-16" xyz="0 0.006375 -0.21038"/>
        <parent link="righthalf_arm_2_link"/>
        <child link="rightforearm_link"/>
        <axis xyz="0 0 1"/>
        <limit effort="39" lower="-2.66" upper="2.66" velocity="1.3963"/>
    </joint>
    <link name="rightspherical_wrist_1_link">

        <inertial>
            <origin rpy="0 0 0" xyz="1E-06 -0.009432 -0.063883"/>
            <mass value="0.6781"/>
            <inertia ixx="0.001596" ixy="0" ixz="0" iyy="0.001607" iyz="0.000256" izz="0.000399"/>
        </inertial>

        <visual>
            <origin rpy="0 0 0" xyz="0 0 0"/>
            <geometry>
                <mesh filename="package://kortex_description/arms/gen3/7dof/meshes/spherical_wrist_1_link.STL"/>
            </geometry>
            <material name="">
                <color rgba="0.75294 0.75294 0.75294 1"/>
            </material>
        </visual>
        <collision>
            <origin rpy="0 0 0" xyz="0 0 0"/>
            <geometry>
                <mesh filename="package://kortex_description/arms/gen3/7dof/meshes/spherical_wrist_1_link.STL"/>
            </geometry>
        </collision>
    </link>
    <joint name="rightjoint_5" type="continuous">
        <origin rpy="-1.5708 2.2204E-16 -6.373E-17" xyz="0 -0.20843 -0.006375"/>
        <parent link="rightforearm_link"/>
        <child link="rightspherical_wrist_1_link"/>
        <axis xyz="0 0 1"/>
        <limit effort="9" velocity="1.2218"/>
    </joint>
    <link name="rightspherical_wrist_2_link">

        <inertial>
            <origin rpy="0 0 0" xyz="1E-06 -0.045483 -0.00965"/>
            <mass value="0.6781"/>
            <inertia ixx="0.001641" ixy="0" ixz="0" iyy="0.00041" iyz="-0.000278" izz="0.001641"/>
        </inertial>

        <visual>
            <origin rpy="0 0 0" xyz="0 0 0"/>
            <geometry>
                <mesh filename="package://kortex_description/arms/gen3/7dof/meshes/spherical_wrist_2_link.STL"/>
            </geometry>
            <material name="">
                <color rgba="0.75294 0.75294 0.75294 1"/>
            </material>
        </visual>
        <collision>
            <origin rpy="0 0 0" xyz="0 0 0"/>
            <geometry>
                <mesh filename="package://kortex_description/arms/gen3/7dof/meshes/spherical_wrist_2_link.STL"/>
            </geometry>
        </collision>
    </link>
    <joint name="rightjoint_6" type="revolute">
        <origin rpy="1.5708 9.2076E-28 -8.2157E-15" xyz="0 0.00017505 -0.10593"/>
        <parent link="rightspherical_wrist_1_link"/>
        <child link="rightspherical_wrist_2_link"/>
        <axis xyz="0 0 1"/>
        <limit effort="9" lower="-2.23" upper="2.23" velocity="1.2218"/>
    </joint>
    <link name="rightbracelet_link">

        <inertial>
            <origin rpy="0 0 0" xyz="0.000281 0.011402 -0.029798"/>
            <mass value="0.5"/>
            <inertia ixx="0.000587" ixy="3E-06" ixz="3E-06" iyy="0.000369" iyz="-0.000118" izz="0.000609"/>
        </inertial>

        <visual>
            <origin rpy="0 0 0" xyz="0 0 0"/>
            <geometry>
                <mesh filename="package://kortex_description/arms/gen3/7dof/meshes/bracelet_with_vision_link.STL"/>
            </geometry>
            <material name="">
                <color rgba="0.75294 0.75294 0.75294 1"/>
            </material>
        </visual>
        <collision>
            <origin rpy="0 0 0" xyz="0 0 0"/>
            <geometry>
                <mesh filename="package://kortex_description/arms/gen3/7dof/meshes/bracelet_with_vision_link.STL"/>
            </geometry>
        </collision>
    </link>
    <joint name="rightjoint_7" type="continuous">
        <origin rpy="-1.5708 -5.5511E-17 9.6396E-17" xyz="0 -0.10593 -0.00017505"/>
        <parent link="rightspherical_wrist_2_link"/>
        <child link="rightbracelet_link"/>
        <axis xyz="0 0 1"/>
        <limit effort="9" velocity="1.2218"/>
    </joint>
    <link name="rightend_effector_link"/>
    <joint name="rightend_effector" type="fixed">
        <origin rpy="3.14159265358979 1.09937075168372E-32 0" xyz="0 0 -0.0615250000000001"/>
        <parent link="rightbracelet_link"/>
        <child link="rightend_effector_link"/>
        <axis xyz="0 0 0"/>
    </joint>

    <link name="camera">
        <visual>
            <geometry>
                <box size="0.01 0.01 0.01"/>
            </geometry>
            <origin rpy="0 0 0" xyz="0 0 0"/>
            <material name="red"/>
        </visual>
        <inertial>
            <mass value="0.1"/>
            <inertia ixx="0.03" ixy="0.0" ixz="0.0" iyy="0.03" iyz="0.0" izz="0.03"/>
        </inertial>
    </link>

    <joint name="fixed_camera" type="fixed">
        <origin xyz="0 0 0" rpy="0 -1.57 0"/>
        <parent link="leftend_effector_link"/>
        <child link="camera"/>
    </joint>
    <!-- This line was removed by Kinova because we replaced the transmission file with our own
    <xacro:include filename="$(find robotiq_2f_85_gripper_visualization)/urdf/robotiq_arg2f_transmission.xacro" /> -->
    <!-- This joint was added by Kinova -->

    <transmission name="trans_leftjoint_1">
        <type>transmission_interface/SimpleTransmission</type>
        <joint name="leftjoint_1">
            <hardwareInterface>hardware_interface/EffortJointInterface</hardwareInterface>
        </joint>
        <actuator name="leftjoint_1_motor">
            <hardwareInterface>hardware_interface/EffortJointInterface</hardwareInterface>
            <mechanicalReduction>1</mechanicalReduction>
        </actuator>
    </transmission>
    <transmission name="trans_leftjoint_2">
        <type>transmission_interface/SimpleTransmission</type>
        <joint name="leftjoint_2">
            <hardwareInterface>hardware_interface/EffortJointInterface</hardwareInterface>
        </joint>
        <actuator name="leftjoint_2_motor">
            <hardwareInterface>hardware_interface/EffortJointInterface</hardwareInterface>
            <mechanicalReduction>1</mechanicalReduction>
        </actuator>
    </transmission>
    <transmission name="trans_leftjoint_3">
        <type>transmission_interface/SimpleTransmission</type>
        <joint name="leftjoint_3">
            <hardwareInterface>hardware_interface/EffortJointInterface</hardwareInterface>
        </joint>
        <actuator name="leftjoint_3_motor">
            <hardwareInterface>hardware_interface/EffortJointInterface</hardwareInterface>
            <mechanicalReduction>1</mechanicalReduction>
        </actuator>
    </transmission>
    <transmission name="trans_leftjoint_4">
        <type>transmission_interface/SimpleTransmission</type>
        <joint name="leftjoint_4">
            <hardwareInterface>hardware_interface/EffortJointInterface</hardwareInterface>
        </joint>
        <actuator name="leftjoint_4_motor">
            <hardwareInterface>hardware_interface/EffortJointInterface</hardwareInterface>
            <mechanicalReduction>1</mechanicalReduction>
        </actuator>
    </transmission>
    <transmission name="trans_leftjoint_5">
        <type>transmission_interface/SimpleTransmission</type>
        <joint name="leftjoint_5">
            <hardwareInterface>hardware_interface/EffortJointInterface</hardwareInterface>
        </joint>
        <actuator name="leftjoint_5_motor">
            <hardwareInterface>hardware_interface/EffortJointInterface</hardwareInterface>
            <mechanicalReduction>1</mechanicalReduction>
        </actuator>
    </transmission>
    <transmission name="trans_leftjoint_6">
        <type>transmission_interface/SimpleTransmission</type>
        <joint name="leftjoint_6">
            <hardwareInterface>hardware_interface/EffortJointInterface</hardwareInterface>
        </joint>
        <actuator name="leftjoint_6_motor">
            <hardwareInterface>hardware_interface/EffortJointInterface</hardwareInterface>
            <mechanicalReduction>1</mechanicalReduction>
        </actuator>
    </transmission>
    <transmission name="trans_leftjoint_7">
        <type>transmission_interface/SimpleTransmission</type>
        <joint name="leftjoint_7">
            <hardwareInterface>hardware_interface/EffortJointInterface</hardwareInterface>
        </joint>
        <actuator name="leftjoint_7_motor">
            <hardwareInterface>hardware_interface/EffortJointInterface</hardwareInterface>
            <mechanicalReduction>1</mechanicalReduction>
        </actuator>
    </transmission>
    <transmission name="trans_rightjoint_1">
        <type>transmission_interface/SimpleTransmission</type>
        <joint name="rightjoint_1">
            <hardwareInterface>hardware_interface/EffortJointInterface</hardwareInterface>
        </joint>
        <actuator name="rightjoint_1_motor">
            <hardwareInterface>hardware_interface/EffortJointInterface</hardwareInterface>
            <mechanicalReduction>1</mechanicalReduction>
        </actuator>
    </transmission>
    <transmission name="trans_rightjoint_2">
        <type>transmission_interface/SimpleTransmission</type>
        <joint name="rightjoint_2">
            <hardwareInterface>hardware_interface/EffortJointInterface</hardwareInterface>
        </joint>
        <actuator name="rightjoint_2_motor">
            <hardwareInterface>hardware_interface/EffortJointInterface</hardwareInterface>
            <mechanicalReduction>1</mechanicalReduction>
        </actuator>
    </transmission>
    <transmission name="trans_rightjoint_3">
        <type>transmission_interface/SimpleTransmission</type>
        <joint name="rightjoint_3">
            <hardwareInterface>hardware_interface/EffortJointInterface</hardwareInterface>
        </joint>
        <actuator name="rightjoint_3_motor">
            <hardwareInterface>hardware_interface/EffortJointInterface</hardwareInterface>
            <mechanicalReduction>1</mechanicalReduction>
        </actuator>
    </transmission>
    <transmission name="trans_rightjoint_4">
        <type>transmission_interface/SimpleTransmission</type>
        <joint name="rightjoint_4">
            <hardwareInterface>hardware_interface/EffortJointInterface</hardwareInterface>
        </joint>
        <actuator name="rightjoint_4_motor">
            <hardwareInterface>hardware_interface/EffortJointInterface</hardwareInterface>
            <mechanicalReduction>1</mechanicalReduction>
        </actuator>
    </transmission>
    <transmission name="trans_rightjoint_5">
        <type>transmission_interface/SimpleTransmission</type>
        <joint name="rightjoint_5">
            <hardwareInterface>hardware_interface/EffortJointInterface</hardwareInterface>
        </joint>
        <actuator name="rightjoint_5_motor">
            <hardwareInterface>hardware_interface/EffortJointInterface</hardwareInterface>
            <mechanicalReduction>1</mechanicalReduction>
        </actuator>
    </transmission>
    <transmission name="trans_rightjoint_6">
        <type>transmission_interface/SimpleTransmission</type>
        <joint name="rightjoint_6">
            <hardwareInterface>hardware_interface/EffortJointInterface</hardwareInterface>
        </joint>
        <actuator name="rightjoint_6_motor">
            <hardwareInterface>hardware_interface/EffortJointInterface</hardwareInterface>
            <mechanicalReduction>1</mechanicalReduction>
        </actuator>
    </transmission>
    <transmission name="trans_rightjoint_7">
        <type>transmission_interface/SimpleTransmission</type>
        <joint name="rightjoint_7">
            <hardwareInterface>hardware_interface/EffortJointInterface</hardwareInterface>
        </joint>
        <actuator name="rightjoint_7_motor">
            <hardwareInterface>hardware_interface/EffortJointInterface</hardwareInterface>
            <mechanicalReduction>1</mechanicalReduction>
        </actuator>
    </transmission>

    <gazebo>
        <plugin name="gazebo_ros_control" filename="libgazebo_ros_control.so">
            <robotNamespace>/</robotNamespace>
        </plugin>
    </gazebo>
    <gazebo reference="camera">
        <material>Gazebo/Red</material>
        <sensor type="camera" name="camera">
            <update_rate>30.0</update_rate>
            <camera name="head">
                <horizontal_fov>1.3962634</horizontal_fov>
                <image>
                    <width>800</width>
                    <height>800</height>
                    <format>R8G8B8</format>
                </image>
                <clip>
                    <near>0.02</near>
                    <far>300</far>
                </clip>
                <noise>
                    <type>gaussian</type>
                    <!-- Noise is sampled independently per pixel on each frame.
                         That pixel's noise value is added to each of its color
                         channels, which at that point lie in the range [0,1]. -->
                    <mean>0.0</mean>
                    <stddev>0.007</stddev>
                </noise>
            </camera>
            <plugin name="camera_controller" filename="libgazebo_ros_camera.so">
                <alwaysOn>true</alwaysOn>
                <updateRate>0.0</updateRate>
                <cameraName>/cam/camera</cameraName>
                <imageTopicName>image_raw</imageTopicName>
                <cameraInfoTopicName>camera_info</cameraInfoTopicName>
                <frameName>camera</frameName>
                <hackBaseline>0.07</hackBaseline>
                <distortionK1>0.0</distortionK1>
                <distortionK2>0.0</distortionK2>
                <distortionK3>0.0</distortionK3>
                <distortionT1>0.0</distortionT1>
                <distortionT2>0.0</distortionT2>
            </plugin>
        </sensor>
    </gazebo>
</robot>